Database Manager Launched
User Manager Launched
Network Service Manager Launched
Traceback (most recent call last):
  File "main.py", line 10, in <module>
    erp_server = ServerSystem.ServerSystem(sys.argv[1], int(sys.argv[2]))
  File "/root/Git-Repository/ERP-Sandbox-Simulator-Alpha/ERP-Simulator-Server-End/ServerSystem.py", line 20, in __init__
    self.__server_socket = ServerNetwork.ServerSocket(_ip, _p, self.__service_manager)
  File "/root/Git-Repository/ERP-Sandbox-Simulator-Alpha/ERP-Simulator-Server-End/ServerNetwork.py", line 17, in __init__
    self.__socket.bind((self.__host_ip, self.__port))
OSError: [Errno 98] Address already in use
Traceback (most recent call last):
  File "main.py", line 10, in <module>
    erp_server = ServerSystem.ServerSystem(sys.argv[1], int(sys.argv[2]))
IndexError: list index out of range
Database Manager Launched
User Manager Launched
Network Service Manager Launched
Traceback (most recent call last):
  File "main.py", line 10, in <module>
    erp_server = ServerSystem.ServerSystem(sys.argv[1], int(sys.argv[2]))
  File "/root/Git-Repository/ERP-Sandbox-Simulator-Alpha/ERP-Simulator-Server-End/ServerSystem.py", line 20, in __init__
    self.__server_socket = ServerNetwork.ServerSocket(_ip, _p, self.__service_manager)
  File "/root/Git-Repository/ERP-Sandbox-Simulator-Alpha/ERP-Simulator-Server-End/ServerNetwork.py", line 17, in __init__
    self.__socket.bind((self.__host_ip, self.__port))
OSError: [Errno 98] Address already in use
Database Manager Launched
User Manager Launched
Network Service Manager Launched
Traceback (most recent call last):
  File "main.py", line 11, in <module>
    erp_server = ServerSystem.ServerSystem('140.82.1.250',8828)
  File "/root/Git-Repository/ERP-Sandbox-Simulator-Alpha/ERP-Simulator-Server-End/ServerSystem.py", line 20, in __init__
    self.__server_socket = ServerNetwork.ServerSocket(_ip, _p, self.__service_manager)
  File "/root/Git-Repository/ERP-Sandbox-Simulator-Alpha/ERP-Simulator-Server-End/ServerNetwork.py", line 17, in __init__
    self.__socket.bind((self.__host_ip, self.__port))
OSError: [Errno 98] Address already in use
